{"trial_id": "0059", "hyperparameters": {"space": [{"class_name": "Choice", "config": {"name": "activation", "default": "relu", "conditions": [], "values": ["relu", "tanh", "sigmoid"], "ordered": false}}, {"class_name": "Int", "config": {"name": "first_units", "default": null, "conditions": [], "min_value": 1, "max_value": 30, "step": 2, "sampling": "linear"}}, {"class_name": "Int", "config": {"name": "num_layers", "default": null, "conditions": [], "min_value": 1, "max_value": 6, "step": 1, "sampling": "linear"}}, {"class_name": "Int", "config": {"name": "units_0", "default": null, "conditions": [], "min_value": 1, "max_value": 30, "step": 2, "sampling": "linear"}}, {"class_name": "Int", "config": {"name": "units_1", "default": null, "conditions": [], "min_value": 1, "max_value": 30, "step": 2, "sampling": "linear"}}, {"class_name": "Int", "config": {"name": "units_2", "default": null, "conditions": [], "min_value": 1, "max_value": 30, "step": 2, "sampling": "linear"}}, {"class_name": "Int", "config": {"name": "units_3", "default": null, "conditions": [], "min_value": 1, "max_value": 30, "step": 2, "sampling": "linear"}}, {"class_name": "Int", "config": {"name": "units_4", "default": null, "conditions": [], "min_value": 1, "max_value": 30, "step": 2, "sampling": "linear"}}, {"class_name": "Int", "config": {"name": "units_5", "default": null, "conditions": [], "min_value": 1, "max_value": 30, "step": 2, "sampling": "linear"}}], "values": {"activation": "tanh", "first_units": 9, "num_layers": 2, "units_0": 21, "units_1": 5, "units_2": 15, "units_3": 17, "units_4": 1, "units_5": 3, "tuner/epochs": 6, "tuner/initial_epoch": 0, "tuner/bracket": 2, "tuner/round": 0}}, "metrics": {"metrics": {}}, "score": null, "best_step": 0, "status": "FAILED", "message": "Traceback (most recent call last):\n  File \"/Users/saudiaepps/anaconda3/envs/dev/lib/python3.11/site-packages/keras_tuner/src/engine/base_tuner.py\", line 274, in _try_run_and_update_trial\n    self._run_and_update_trial(trial, *fit_args, **fit_kwargs)\n  File \"/Users/saudiaepps/anaconda3/envs/dev/lib/python3.11/site-packages/keras_tuner/src/engine/base_tuner.py\", line 239, in _run_and_update_trial\n    results = self.run_trial(trial, *fit_args, **fit_kwargs)\n              ^^^^^^^^^^^^^^^^^^^^^^^^^^^^^^^^^^^^^^^^^^^^^^\n  File \"/Users/saudiaepps/anaconda3/envs/dev/lib/python3.11/site-packages/keras_tuner/src/tuners/hyperband.py\", line 427, in run_trial\n    return super().run_trial(trial, *fit_args, **fit_kwargs)\n           ^^^^^^^^^^^^^^^^^^^^^^^^^^^^^^^^^^^^^^^^^^^^^^^^^\n  File \"/Users/saudiaepps/anaconda3/envs/dev/lib/python3.11/site-packages/keras_tuner/src/engine/tuner.py\", line 314, in run_trial\n    obj_value = self._build_and_fit_model(trial, *args, **copied_kwargs)\n                ^^^^^^^^^^^^^^^^^^^^^^^^^^^^^^^^^^^^^^^^^^^^^^^^^^^^^^^^\n  File \"/Users/saudiaepps/anaconda3/envs/dev/lib/python3.11/site-packages/keras_tuner/src/engine/tuner.py\", line 233, in _build_and_fit_model\n    results = self.hypermodel.fit(hp, model, *args, **kwargs)\n              ^^^^^^^^^^^^^^^^^^^^^^^^^^^^^^^^^^^^^^^^^^^^^^^\n  File \"/Users/saudiaepps/anaconda3/envs/dev/lib/python3.11/site-packages/keras_tuner/src/engine/hypermodel.py\", line 149, in fit\n    return model.fit(*args, **kwargs)\n           ^^^^^^^^^^^^^^^^^^^^^^^^^^\n  File \"/Users/saudiaepps/anaconda3/envs/dev/lib/python3.11/site-packages/keras/src/utils/traceback_utils.py\", line 122, in error_handler\n    raise e.with_traceback(filtered_tb) from None\n  File \"/Users/saudiaepps/anaconda3/envs/dev/lib/python3.11/site-packages/tensorflow/python/eager/execute.py\", line 59, in quick_execute\n    except TypeError as e:\ntensorflow.python.framework.errors_impl.InvalidArgumentError: Graph execution error:\n\nDetected at node adam/truediv_1 defined at (most recent call last):\n  File \"<frozen runpy>\", line 198, in _run_module_as_main\n\n  File \"<frozen runpy>\", line 88, in _run_code\n\n  File \"/Users/saudiaepps/anaconda3/envs/dev/lib/python3.11/site-packages/ipykernel_launcher.py\", line 17, in <module>\n\n  File \"/Users/saudiaepps/anaconda3/envs/dev/lib/python3.11/site-packages/traitlets/config/application.py\", line 992, in launch_instance\n\n  File \"/Users/saudiaepps/anaconda3/envs/dev/lib/python3.11/site-packages/ipykernel/kernelapp.py\", line 736, in start\n\n  File \"/Users/saudiaepps/anaconda3/envs/dev/lib/python3.11/site-packages/tornado/platform/asyncio.py\", line 195, in start\n\n  File \"/Users/saudiaepps/anaconda3/envs/dev/lib/python3.11/asyncio/base_events.py\", line 607, in run_forever\n\n  File \"/Users/saudiaepps/anaconda3/envs/dev/lib/python3.11/asyncio/base_events.py\", line 1922, in _run_once\n\n  File \"/Users/saudiaepps/anaconda3/envs/dev/lib/python3.11/asyncio/events.py\", line 80, in _run\n\n  File \"/Users/saudiaepps/anaconda3/envs/dev/lib/python3.11/site-packages/ipykernel/kernelbase.py\", line 516, in dispatch_queue\n\n  File \"/Users/saudiaepps/anaconda3/envs/dev/lib/python3.11/site-packages/ipykernel/kernelbase.py\", line 505, in process_one\n\n  File \"/Users/saudiaepps/anaconda3/envs/dev/lib/python3.11/site-packages/ipykernel/kernelbase.py\", line 412, in dispatch_shell\n\n  File \"/Users/saudiaepps/anaconda3/envs/dev/lib/python3.11/site-packages/ipykernel/kernelbase.py\", line 740, in execute_request\n\n  File \"/Users/saudiaepps/anaconda3/envs/dev/lib/python3.11/site-packages/ipykernel/ipkernel.py\", line 422, in do_execute\n\n  File \"/Users/saudiaepps/anaconda3/envs/dev/lib/python3.11/site-packages/ipykernel/zmqshell.py\", line 546, in run_cell\n\n  File \"/Users/saudiaepps/anaconda3/envs/dev/lib/python3.11/site-packages/IPython/core/interactiveshell.py\", line 3024, in run_cell\n\n  File \"/Users/saudiaepps/anaconda3/envs/dev/lib/python3.11/site-packages/IPython/core/interactiveshell.py\", line 3079, in _run_cell\n\n  File \"/Users/saudiaepps/anaconda3/envs/dev/lib/python3.11/site-packages/IPython/core/async_helpers.py\", line 129, in _pseudo_sync_runner\n\n  File \"/Users/saudiaepps/anaconda3/envs/dev/lib/python3.11/site-packages/IPython/core/interactiveshell.py\", line 3284, in run_cell_async\n\n  File \"/Users/saudiaepps/anaconda3/envs/dev/lib/python3.11/site-packages/IPython/core/interactiveshell.py\", line 3466, in run_ast_nodes\n\n  File \"/Users/saudiaepps/anaconda3/envs/dev/lib/python3.11/site-packages/IPython/core/interactiveshell.py\", line 3526, in run_code\n\n  File \"/var/folders/gf/7_p3sxw10d1388jbztt0s3340000gn/T/ipykernel_41109/3294167552.py\", line 7, in <module>\n\n  File \"/Users/saudiaepps/anaconda3/envs/dev/lib/python3.11/site-packages/keras_tuner/src/engine/base_tuner.py\", line 234, in search\n\n  File \"/Users/saudiaepps/anaconda3/envs/dev/lib/python3.11/site-packages/keras_tuner/src/engine/base_tuner.py\", line 274, in _try_run_and_update_trial\n\n  File \"/Users/saudiaepps/anaconda3/envs/dev/lib/python3.11/site-packages/keras_tuner/src/engine/base_tuner.py\", line 239, in _run_and_update_trial\n\n  File \"/Users/saudiaepps/anaconda3/envs/dev/lib/python3.11/site-packages/keras_tuner/src/tuners/hyperband.py\", line 427, in run_trial\n\n  File \"/Users/saudiaepps/anaconda3/envs/dev/lib/python3.11/site-packages/keras_tuner/src/engine/tuner.py\", line 314, in run_trial\n\n  File \"/Users/saudiaepps/anaconda3/envs/dev/lib/python3.11/site-packages/keras_tuner/src/engine/tuner.py\", line 233, in _build_and_fit_model\n\n  File \"/Users/saudiaepps/anaconda3/envs/dev/lib/python3.11/site-packages/keras_tuner/src/engine/hypermodel.py\", line 149, in fit\n\n  File \"/Users/saudiaepps/anaconda3/envs/dev/lib/python3.11/site-packages/keras/src/utils/traceback_utils.py\", line 117, in error_handler\n\n  File \"/Users/saudiaepps/anaconda3/envs/dev/lib/python3.11/site-packages/keras/src/backend/tensorflow/trainer.py\", line 314, in fit\n\n  File \"/Users/saudiaepps/anaconda3/envs/dev/lib/python3.11/site-packages/keras/src/backend/tensorflow/trainer.py\", line 117, in one_step_on_iterator\n\n  File \"/Users/saudiaepps/anaconda3/envs/dev/lib/python3.11/site-packages/keras/src/backend/tensorflow/trainer.py\", line 104, in one_step_on_data\n\n  File \"/Users/saudiaepps/anaconda3/envs/dev/lib/python3.11/site-packages/keras/src/backend/tensorflow/trainer.py\", line 69, in train_step\n\n  File \"/Users/saudiaepps/anaconda3/envs/dev/lib/python3.11/site-packages/keras/src/optimizers/base_optimizer.py\", line 282, in apply_gradients\n\n  File \"/Users/saudiaepps/anaconda3/envs/dev/lib/python3.11/site-packages/keras/src/optimizers/base_optimizer.py\", line 351, in apply\n\n  File \"/Users/saudiaepps/anaconda3/envs/dev/lib/python3.11/site-packages/keras/src/optimizers/base_optimizer.py\", line 405, in _backend_apply_gradients\n\n  File \"/Users/saudiaepps/anaconda3/envs/dev/lib/python3.11/site-packages/keras/src/backend/tensorflow/optimizer.py\", line 119, in _backend_update_step\n\n  File \"/Users/saudiaepps/anaconda3/envs/dev/lib/python3.11/site-packages/keras/src/backend/tensorflow/optimizer.py\", line 135, in _distributed_tf_update_step\n\n  File \"/Users/saudiaepps/anaconda3/envs/dev/lib/python3.11/site-packages/keras/src/backend/tensorflow/optimizer.py\", line 132, in apply_grad_to_update_var\n\n  File \"/Users/saudiaepps/anaconda3/envs/dev/lib/python3.11/site-packages/keras/src/optimizers/adam.py\", line 147, in update_step\n\n  File \"/Users/saudiaepps/anaconda3/envs/dev/lib/python3.11/site-packages/keras/src/ops/numpy.py\", line 5502, in divide\n\n  File \"/Users/saudiaepps/anaconda3/envs/dev/lib/python3.11/site-packages/keras/src/backend/tensorflow/sparse.py\", line 780, in sparse_wrapper\n\n  File \"/Users/saudiaepps/anaconda3/envs/dev/lib/python3.11/site-packages/keras/src/backend/tensorflow/numpy.py\", line 2214, in divide\n\nIncompatible shapes: [43,9] vs. [0]\n\t [[{{node adam/truediv_1}}]] [Op:__inference_one_step_on_iterator_767891]\n"}